Traceback with variables (most recent call last):
  File "...omitted for tests only.../test_core.py", line...omitted for tests only..., in check_
    f()
      kwargs = {'fmt': traceback_with_variables.core.Format(after=0, before=0, brief_files_except=[], color_scheme=None, custom_var_printers=[], ellipsis_='...', ellipsis_rel_pos=0.0, max_exc_str_len=10000, max_value_str_len=1000, objects_details=1, skip_files_except=[])}
      tb_reg = <bound method Reg.match_tb_text of <tests.test_utils.Reg object at 0x...omitted for tests only...>>
  File "...omitted for tests only.../dummies.py", line...omitted for tests only..., in f
    return f(
      n = 10001
      s1 = 'short string with n: 10001'
      l1 = ... 9835, 9836, 9837, 9838, 9839, 9840, 9841, 9842, 9843, 9844, 9845, 9846, 9847, 9848, 9849, 9850, 9851, 9852, 9853, 9854, 9855, 9856, 9857, 9858, 9859, 9860, 9861, 9862, 9863, 9864, 9865, 9866, 9867, 9868, 9869, 9870, 9871, 9872, 9873, 9874, 9875, 9876, 9877, 9878, 9879, 9880, 9881, 9882, 9883, 9884, 9885, 9886, 9887, 9888, 9889, 9890, 9891, 9892, 9893, 9894, 9895, 9896, 9897, 9898, 9899, 9900, 9901, 9902, 9903, 9904, 9905, 9906, 9907, 9908, 9909, 9910, 9911, 9912, 9913, 9914, 9915, 9916, 9917, 9918, 9919, 9920, 9921, 9922, 9923, 9924, 9925, 9926, 9927, 9928, 9929, 9930, 9931, 9932, 9933, 9934, 9935, 9936, 9937, 9938, 9939, 9940, 9941, 9942, 9943, 9944, 9945, 9946, 9947, 9948, 9949, 9950, 9951, 9952, 9953, 9954, 9955, 9956, 9957, 9958, 9959, 9960, 9961, 9962, 9963, 9964, 9965, 9966, 9967, 9968, 9969, 9970, 9971, 9972, 9973, 9974, 9975, 9976, 9977, 9978, 9979, 9980, 9981, 9982, 9983, 9984, 9985, 9986, 9987, 9988, 9989, 9990, 9991, 9992, 9993, 9994, 9995, 9996, 9997, 9998, 9999, 10000'
      us = <exception while printing> Traceback (most recent call last):
          ...traceback_with_variables internal stacks...
          File "...omitted for tests only.../dummies.py", line...omitted for tests only..., in __repr__
            raise ValueError("please don't print me")
        ValueError: please don't print me
        
  File "...omitted for tests only.../dummies.py", line...omitted for tests only..., in f
    return 1 // (n * 0)
      n = 10000
      s1 = 'short string with n: 10000'
      l1 = ..., 9834, 9835, 9836, 9837, 9838, 9839, 9840, 9841, 9842, 9843, 9844, 9845, 9846, 9847, 9848, 9849, 9850, 9851, 9852, 9853, 9854, 9855, 9856, 9857, 9858, 9859, 9860, 9861, 9862, 9863, 9864, 9865, 9866, 9867, 9868, 9869, 9870, 9871, 9872, 9873, 9874, 9875, 9876, 9877, 9878, 9879, 9880, 9881, 9882, 9883, 9884, 9885, 9886, 9887, 9888, 9889, 9890, 9891, 9892, 9893, 9894, 9895, 9896, 9897, 9898, 9899, 9900, 9901, 9902, 9903, 9904, 9905, 9906, 9907, 9908, 9909, 9910, 9911, 9912, 9913, 9914, 9915, 9916, 9917, 9918, 9919, 9920, 9921, 9922, 9923, 9924, 9925, 9926, 9927, 9928, 9929, 9930, 9931, 9932, 9933, 9934, 9935, 9936, 9937, 9938, 9939, 9940, 9941, 9942, 9943, 9944, 9945, 9946, 9947, 9948, 9949, 9950, 9951, 9952, 9953, 9954, 9955, 9956, 9957, 9958, 9959, 9960, 9961, 9962, 9963, 9964, 9965, 9966, 9967, 9968, 9969, 9970, 9971, 9972, 9973, 9974, 9975, 9976, 9977, 9978, 9979, 9980, 9981, 9982, 9983, 9984, 9985, 9986, 9987, 9988, 9989, 9990, 9991, 9992, 9993, 9994, 9995, 9996, 9997, 9998, 9999'
      us = <exception while printing> Traceback (most recent call last):
          ...traceback_with_variables internal stacks...
          File "...omitted for tests only.../dummies.py", line...omitted for tests only..., in __repr__
            raise ValueError("please don't print me")
        ValueError: please don't print me
        
builtins.ZeroDivisionError: integer division or modulo by zero