Traceback with variables (most recent call last):
  File "...omitted for tests only, abs path.../test_default_global_hooks.py", line 25, in check
    f()
      tb_reg = <bound method Reg.match_tb_text of <tests.test_utils.Reg object at 0x...omitted for tests only, obj id...>>
      fmt = traceback_with_variables.core.Format(after=0, before=0, brief_files_except=[], color_scheme=None, custom_var_printers=[(<function _var_filter_to_should_print.<locals>.should_print at 0x...omitted for tests only, obj id...>, <function hide at 0x...omitted for tests only, obj id...>)], ellipsis_='...', ellipsis_rel_pos=0.7, max_exc_str_len=10000, max_value_str_len=1000, objects_details=1, skip_files_except=[])
  File "...omitted for tests only, abs path.../test_default_global_hooks.py", line 18, in f
    return f(n - 1)
      n = 1
      money = '1000'
      password = ...hidden...
      secret_word = ...hidden...
      monkey_species = ...hidden...
      my_pAssWOrd_2 = ...hidden...
      mySecretN = ...hidden...
      card_number = '1234 5678 1234 5678'
  File "...omitted for tests only, abs path.../test_default_global_hooks.py", line 20, in f
    raise ValueError('planned exception')
      n = 0
      money = '1000'
      password = ...hidden...
      secret_word = ...hidden...
      monkey_species = ...hidden...
      my_pAssWOrd_2 = ...hidden...
      mySecretN = ...hidden...
      card_number = '1234 5678 1234 5678'
builtins.ValueError: planned exception